Workbook
Name Slicer_Full_Name: #N/A
Name Slicer_Month: #N/A
Name Slicer_Reason_For_Visit: #N/A
Name Slicer_Treatment_Type: #N/A
Name Timeline_Bill_Date: #N/A

Sheet APPOIN OG
A1: Appointment_Id | B1: Patient_Id | C1: Doctor_Id | D1: Appointment_Date | E1: Appointment_Time | F1: Reason_For_Visit | G1: Status
A2: A001 | B2: P034 | C2: D009 | D2: 45147 | E2: 0.63541667 | F2: Therapy | G2: Scheduled
A3: A002 | B3: P032 | C3: D004 | D3: 45086 | E3: 0.60416667 | F3: Therapy | G3: No-show
A4: A003 | B4: P048 | C4: D004 | D4: 45105 | E4: 0.33333333 | F4: Consultation | G4: Cancelled
A5: A004 | B5: P025 | C5: D006 | D5: 45170 | E5: 0.38541667 | F5: Consultation | G5: Cancelled
A6: A005 | B6: P040 | C6: D003 | D6: 45113 | E6: 0.53125 | F6: Emergency | G6: No-show
A7: A006 | B7: P045 | C7: D006 | D7: 45096 | E7: 0.67708333 | F7: Checkup | G7: Scheduled
A8: A007 | B8: P001 | C8: D007 | D8: 45025 | E8: 0.4375 | F8: Consultation | G8: Scheduled
A9: A008 | B9: P016 | C9: D010 | D9: 45070 | E9: 0.36458333 | F9: Consultation | G9: Cancelled
A10: A009 | B10: P039 | C10: D010 | D10: 44990 | E10: 0.57291667 | F10: Follow-up | G10: Scheduled
A11: A010 | B11: P005 | C11: D003 | D11: 44939 | E11: 0.64583333 | F11: Therapy | G11: Completed
A12: A011 | B12: P022 | C12: D007 | D12: 45242 | E12: 0.66666667 | F12: Checkup | G12: No-show
A13: A012 | B13: P029 | C13: D003 | D13: 45053 | E13: 0.41666667 | F13: Follow-up | G13: Completed
... A201: A200 | B201: P007 | C201: D005 | D201: 45290 | E201: 0.42708333 | F201: Consultation | G201: Cancelled

Sheet BILLING OG
A1: Bill_Id | B1: Patient_Id | C1: Treatment_Id | D1: Bill_Date | E1: Month | F1: Amount | G1: Payment_Method | H1: Payment_Status
A2: B001 | B2: P034 | C2: T001 | D2: 45147 | E2: =TEXT(D2,"mmmm-yyyy") -> August-2023 | F2: 3941.97 | G2: Insurance | H2: Pending
A3: B002 | B3: P032 | C3: T002 | D3: 45086 | E3: =TEXT(D3,"mmmm-yyyy") -> June-2023 | F3: 4158.44 | G3: Insurance | H3: Paid
A4: B003 | B4: P048 | C4: T003 | D4: 45105 | E4: =TEXT(D4,"mmmm-yyyy") -> June-2023 | F4: 3731.55 | G4: Insurance | H4: Paid
A5: B004 | B5: P025 | C5: T004 | D5: 45170 | E5: =TEXT(D5,"mmmm-yyyy") -> September-2023 | F5: 4799.86 | G5: Insurance | H5: Failed
A6: B005 | B6: P040 | C6: T005 | D6: 45113 | E6: =TEXT(D6,"mmmm-yyyy") -> July-2023 | F6: 582.05 | G6: Credit Card | H6: Pending
A7: B006 | B7: P045 | C7: T006 | D7: 45096 | E7: =TEXT(D7,"mmmm-yyyy") -> June-2023 | F7: 1381 | G7: Insurance | H7: Pending
A8: B007 | B8: P001 | C8: T007 | D8: 45025 | E8: =TEXT(D8,"mmmm-yyyy") -> April-2023 | F8: 534.03 | G8: Cash | H8: Failed
A9: B008 | B9: P016 | C9: T008 | D9: 45070 | E9: =TEXT(D9,"mmmm-yyyy") -> May-2023 | F9: 3413.64 | G9: Cash | H9: Failed
A10: B009 | B10: P039 | C10: T009 | D10: 44990 | E10: =TEXT(D10,"mmmm-yyyy") -> March-2023 | F10: 4541.14 | G10: Credit Card | H10: Paid
A11: B010 | B11: P005 | C11: T010 | D11: 44939 | E11: =TEXT(D11,"mmmm-yyyy") -> January-2023 | F11: 1595.67 | G11: Cash | H11: Paid
A12: B011 | B12: P022 | C12: T011 | D12: 45242 | E12: =TEXT(D12,"mmmm-yyyy") -> November-2023 | F12: 4671.66 | G12: Cash | H12: Failed
A13: B012 | B13: P029 | C13: T012 | D13: 45053 | E13: =TEXT(D13,"mmmm-yyyy") -> May-2023 | F13: 771.2 | G13: Insurance | H13: Pending
... A201: B200 | B201: P007 | C201: T200 | D201: 45290 | E201: =TEXT(D201,"mmmm-yyyy") -> December-2023 | F201: 3288.15 | G201: Insurance | H201: Paid

Sheet TRETMEN OG
A1: Treatment_Id | B1: Appointment_Id | C1: Treatment_Type | D1: Description | E1: Cost | F1: Treatment_Date
A2: T001 | B2: A001 | C2: Chemotherapy | D2: Basic screening | E2: 3941.97 | F2: 45147
A3: T002 | B3: A002 | C3: MRI | D3: Advanced protocol | E3: 4158.44 | F3: 45086
A4: T003 | B4: A003 | C4: MRI | D4: Standard procedure | E4: 3731.55 | F4: 45105
A5: T004 | B5: A004 | C5: MRI | D5: Basic screening | E5: 4799.86 | F5: 45170
A6: T005 | B6: A005 | C6: ECG | D6: Standard procedure | E6: 582.05 | F6: 45113
A7: T006 | B7: A006 | C7: Chemotherapy | D7: Standard procedure | E7: 1381 | F7: 45096
A8: T007 | B8: A007 | C8: Chemotherapy | D8: Advanced protocol | E8: 534.03 | F8: 45025
A9: T008 | B9: A008 | C9: Physiotherapy | D9: Basic screening | E9: 3413.64 | F9: 45070
A10: T009 | B10: A009 | C10: Physiotherapy | D10: Standard procedure | E10: 4541.14 | F10: 44990
A11: T010 | B11: A010 | C11: Physiotherapy | D11: Standard procedure | E11: 1595.67 | F11: 44939
A12: T011 | B12: A011 | C12: MRI | D12: Basic screening | E12: 4671.66 | F12: 45242
A13: T012 | B13: A012 | C13: Chemotherapy | D13: Standard procedure | E13: 771.2 | F13: 45053
... A201: T200 | B201: A200 | C201: X-Ray | D201: Basic screening | E201: 3288.15 | F201: 45290

Sheet PATIENT OG
A1: Patient_Id | B1: First_Name | C1: Last_Name | D1: Gender | E1: Date_Of_Birth | F1: Contact_Number | G1: Address | H1: Registration_Date | I1: Insurance_Provider | J1: Insurance_Number | K1: Email
A2: P001 | B2: David | C2: Williams | D2: F | E2: 20244 | F2: 6939585183 | G2: 789 Pine Rd | H2: 44735 | I2: WellnessCorp | J2: INS840674 | K2: david.williams@mail.com
A3: P002 | B3: Emily | C3: Smith | D3: F | E3: 30967 | F3: 8228188767 | G3: 321 Maple Dr | H3: 44576 | I3: PulseSecure | J3: INS354079 | K3: emily.smith@mail.com
A4: P003 | B4: Laura | C4: Jones | D4: M | E4: 28358 | F4: 8397029847 | G4: 321 Maple Dr | H4: 44599 | I4: PulseSecure | J4: INS650929 | K4: laura.jones@mail.com
A5: P004 | B5: Michael | C5: Johnson | D5: F | E5: 29637 | F5: 9019443432 | G5: 123 Elm St | H5: 44257 | I5: HealthIndia | J5: INS789944 | K5: michael.johnson@mail.com
A6: P005 | B6: David | C6: Wilson | D6: M | E6: 22090 | F6: 7734463155 | G6: 123 Elm St | H6: 44468 | I6: MedCare Plus | J6: INS788105 | K6: david.wilson@mail.com
A7: P006 | B7: Linda | C7: Jones | D7: M | E7: 23178 | F7: 7561777264 | G7: 321 Maple Dr | H7: 44836 | I7: HealthIndia | J7: INS613758 | K7: linda.jones@mail.com
A8: P007 | B8: Alex | C8: Johnson | D8: F | E8: 32667 | F8: 6278710077 | G8: 789 Pine Rd | H8: 44555 | I8: MedCare Plus | J8: INS465890 | K8: alex.johnson@mail.com
A9: P008 | B9: David | C9: Davis | D9: F | E9: 27946 | F9: 7090558393 | G9: 456 Oak Ave | H9: 44341 | I9: WellnessCorp | J9: INS545101 | K9: david.davis@mail.com
A10: P009 | B10: Laura | C10: Davis | D10: M | E10: 26278 | F10: 7060324619 | G10: 321 Maple Dr | H10: 44822 | I10: PulseSecure | J10: INS136631 | K10: laura.davis@mail.com
A11: P010 | B11: Michael | C11: Taylor | D11: M | E11: 37177 | F11: 7081396733 | G11: 123 Elm St | H11: 44797 | I11: WellnessCorp | J11: INS866577 | K11: michael.taylor@mail.com
A12: P011 | B12: Emily | C12: Jones | D12: F | E12: 24445 | F12: 8990604070 | G12: 789 Pine Rd | H12: 44831 | I12: MedCare Plus | J12: INS172991 | K12: emily.jones@mail.com
A13: P012 | B13: Laura | C13: Davis | D13: F | E13: 33580 | F13: 8135666049 | G13: 321 Maple Dr | H13: 45043 | I13: MedCare Plus | J13: INS104014 | K13: laura.davis@mail.com
... A51: P050 | B51: Laura | C51: Wilson | D51: M | E51: 34330 | F51: 8301134730 | G51: 321 Maple Dr | H51: 45044 | I51: WellnessCorp | J51: INS712210 | K51: laura.wilson@mail.com

Sheet DOCTOR OG
A1: Doctor_Id | B1: First_Name | C1: Last_Name | D1: Full Name | E1: Specialization | F1: Phone_Number | G1: Years_Experience | H1: Hospital_Branch | I1: Email
A2: D001 | B2: David | C2: Taylor | D2: =_xlfn.CONCAT(B2," ",C2) -> David Taylor | E2: Dermatology | F2: 8322010158 | G2: 17 | H2: Westside Clinic | I2: dr.david.taylor@hospital.com
A3: D002 | B3: Jane | C3: Davis | D3: =_xlfn.CONCAT(B3," ",C3) -> Jane Davis | E3: Pediatrics | F3: 9004382050 | G3: 24 | H3: Eastside Clinic | I3: dr.jane.davis@hospital.com
A4: D003 | B4: Jane | C4: Smith | D4: =_xlfn.CONCAT(B4," ",C4) -> Jane Smith | E4: Pediatrics | F4: 8737740598 | G4: 19 | H4: Eastside Clinic | I4: dr.jane.smith@hospital.com
A5: D004 | B5: David | C5: Jones | D5: =_xlfn.CONCAT(B5," ",C5) -> David Jones | E5: Pediatrics | F5: 6594221991 | G5: 28 | H5: Central Hospital | I5: dr.david.jones@hospital.com
A6: D005 | B6: Sarah | C6: Taylor | D6: =_xlfn.CONCAT(B6," ",C6) -> Sarah Taylor | E6: Dermatology | F6: 9118538547 | G6: 26 | H6: Central Hospital | I6: dr.sarah.taylor@hospital.com
A7: D006 | B7: Alex | C7: Davis | D7: =_xlfn.CONCAT(B7," ",C7) -> Alex Davis | E7: Pediatrics | F7: 6570137231 | G7: 23 | H7: Central Hospital | I7: dr.alex.davis@hospital.com
A8: D007 | B8: Robert | C8: Davis | D8: =_xlfn.CONCAT(B8," ",C8) -> Robert Davis | E8: Oncology | F8: 8217493115 | G8: 26 | H8: Westside Clinic | I8: dr.robert.davis@hospital.com
A9: D008 | B9: Linda | C9: Brown | D9: =_xlfn.CONCAT(B9," ",C9) -> Linda Brown | E9: Dermatology | F9: 9069162601 | G9: 5 | H9: Westside Clinic | I9: dr.linda.brown@hospital.com
A10: D009 | B10: Sarah | C10: Smith | D10: =_xlfn.CONCAT(B10," ",C10) -> Sarah Smith | E10: Pediatrics | F10: 7387087517 | G10: 26 | H10: Central Hospital | I10: dr.sarah.smith@hospital.com
A11: D010 | B11: Linda | C11: Wilson | D11: =_xlfn.CONCAT(B11," ",C11) -> Linda Wilson | E11: Oncology | F11: 6176383634 | G11: 21 | H11: Eastside Clinic | I11: dr.linda.wilson@hospital.com

Sheet Sheet1

Sheet appointments
A1: Appointment_Id | B1: Patient_Id | C1: Doctor_Id | D1: Doctor Name | E1: Appointment_Date | F1: Appointment_Time | G1: Reason_For_Visit | H1: Status
A2: A001 | B2: P034 | C2: D009 | D2: =_xlfn.XLOOKUP(C2,Doctor!$A$1:$A$11,Doctor!$D$1:$D$11) -> Sarah Smith | E2: 45147 | F2: 0.63541667 | G2: Therapy | H2: Scheduled
A3: A002 | B3: P032 | C3: D004 | D3: =_xlfn.XLOOKUP(C3,Doctor!$A$1:$A$11,Doctor!$D$1:$D$11) -> David Jones | E3: 45086 | F3: 0.60416667 | G3: Therapy | H3: No-show
A4: A003 | B4: P048 | C4: D004 | D4: =_xlfn.XLOOKUP(C4,Doctor!$A$1:$A$11,Doctor!$D$1:$D$11) -> David Jones | E4: 45105 | F4: 0.33333333 | G4: Consultation | H4: Cancelled
A5: A004 | B5: P025 | C5: D006 | D5: =_xlfn.XLOOKUP(C5,Doctor!$A$1:$A$11,Doctor!$D$1:$D$11) -> Alex Davis | E5: 45170 | F5: 0.38541667 | G5: Consultation | H5: Cancelled
A6: A005 | B6: P040 | C6: D003 | D6: =_xlfn.XLOOKUP(C6,Doctor!$A$1:$A$11,Doctor!$D$1:$D$11) -> Jane Smith | E6: 45113 | F6: 0.53125 | G6: Emergency | H6: No-show
A7: A006 | B7: P045 | C7: D006 | D7: =_xlfn.XLOOKUP(C7,Doctor!$A$1:$A$11,Doctor!$D$1:$D$11) -> Alex Davis | E7: 45096 | F7: 0.67708333 | G7: Checkup | H7: Scheduled
A8: A007 | B8: P001 | C8: D007 | D8: =_xlfn.XLOOKUP(C8,Doctor!$A$1:$A$11,Doctor!$D$1:$D$11) -> Robert Davis | E8: 45025 | F8: 0.4375 | G8: Consultation | H8: Scheduled
A9: A008 | B9: P016 | C9: D010 | D9: =_xlfn.XLOOKUP(C9,Doctor!$A$1:$A$11,Doctor!$D$1:$D$11) -> Linda Wilson | E9: 45070 | F9: 0.36458333 | G9: Consultation | H9: Cancelled
A10: A009 | B10: P039 | C10: D010 | D10: =_xlfn.XLOOKUP(C10,Doctor!$A$1:$A$11,Doctor!$D$1:$D$11) -> Linda Wilson | E10: 44990 | F10: 0.57291667 | G10: Follow-up | H10: Scheduled
A11: A010 | B11: P005 | C11: D003 | D11: =_xlfn.XLOOKUP(C11,Doctor!$A$1:$A$11,Doctor!$D$1:$D$11) -> Jane Smith | E11: 44939 | F11: 0.64583333 | G11: Therapy | H11: Completed
A12: A011 | B12: P022 | C12: D007 | D12: =_xlfn.XLOOKUP(C12,Doctor!$A$1:$A$11,Doctor!$D$1:$D$11) -> Robert Davis | E12: 45242 | F12: 0.66666667 | G12: Checkup | H12: No-show
A13: A012 | B13: P029 | C13: D003 | D13: =_xlfn.XLOOKUP(C13,Doctor!$A$1:$A$11,Doctor!$D$1:$D$11) -> Jane Smith | E13: 45053 | F13: 0.41666667 | G13: Follow-up | H13: Completed
... A201: A200 | B201: P007 | C201: D005 | D201: =_xlfn.XLOOKUP(C201,Doctor!$A$1:$A$11,Doctor!$D$1:$D$11) -> Sarah Taylor | E201: 45290 | F201: 0.42708333 | G201: Consultation | H201: Cancelled

Sheet Sheet7

Sheet Billing
A1: Bill_Id | B1: Patient_Id | C1: Doctor_Id | D1: Doctor name | E1: Treatment_Id | F1: Treatment_Type | G1: Bill_Date | H1: Month | I1: Amount | J1: Payment_Method | K1: Payment_Status
A2: B001 | B2: P034 | C2: =_xlfn.XLOOKUP(B2,appointments!$B$2:$B$201,appointments!$C$2:$C$201) -> D009 | D2: =_xlfn.XLOOKUP(C2,Doctor!$A$2:$A$11,Doctor!$D$2:$D$11) -> Sarah Smith | E2: T001 | F2: =_xlfn.XLOOKUP(E2,Treatment!$A:$A,Treatment!$C:$C) -> Chemotherapy | G2: 45147 | H2: =TEXT(G2,"mmmm-yyyy") -> August-2023 | I2: 3941.97 | J2: Insurance | K2: Pending
A3: B002 | B3: P032 | C3: =_xlfn.XLOOKUP(B3,appointments!$B$2:$B$201,appointments!$C$2:$C$201) -> D004 | D3: =_xlfn.XLOOKUP(C3,Doctor!$A$2:$A$11,Doctor!$D$2:$D$11) -> David Jones | E3: T002 | F3: =_xlfn.XLOOKUP(E3,Treatment!$A:$A,Treatment!$C:$C) -> MRI | G3: 45086 | H3: =TEXT(G3,"mmmm-yyyy") -> June-2023 | I3: 4158.44 | J3: Insurance | K3: Paid
A4: B003 | B4: P048 | C4: =_xlfn.XLOOKUP(B4,appointments!$B$2:$B$201,appointments!$C$2:$C$201) -> D004 | D4: =_xlfn.XLOOKUP(C4,Doctor!$A$2:$A$11,Doctor!$D$2:$D$11) -> David Jones | E4: T003 | F4: =_xlfn.XLOOKUP(E4,Treatment!$A:$A,Treatment!$C:$C) -> MRI | G4: 45105 | H4: =TEXT(G4,"mmmm-yyyy") -> June-2023 | I4: 3731.55 | J4: Insurance | K4: Paid
A5: B004 | B5: P025 | C5: =_xlfn.XLOOKUP(B5,appointments!$B$2:$B$201,appointments!$C$2:$C$201) -> D006 | D5: =_xlfn.XLOOKUP(C5,Doctor!$A$2:$A$11,Doctor!$D$2:$D$11) -> Alex Davis | E5: T004 | F5: =_xlfn.XLOOKUP(E5,Treatment!$A:$A,Treatment!$C:$C) -> MRI | G5: 45170 | H5: =TEXT(G5,"mmmm-yyyy") -> September-2023 | I5: 4799.86 | J5: Insurance | K5: Failed | M5: Chemotherapy | N5: =SUMIFS($I$2:$I$201,$F$2:$F$201,M5) -> 128855.68
A6: B005 | B6: P040 | C6: =_xlfn.XLOOKUP(B6,appointments!$B$2:$B$201,appointments!$C$2:$C$201) -> D003 | D6: =_xlfn.XLOOKUP(C6,Doctor!$A$2:$A$11,Doctor!$D$2:$D$11) -> Jane Smith | E6: T005 | F6: =_xlfn.XLOOKUP(E6,Treatment!$A:$A,Treatment!$C:$C) -> ECG | G6: 45113 | H6: =TEXT(G6,"mmmm-yyyy") -> July-2023 | I6: 582.05 | J6: Credit Card | K6: Pending | M6: ECG | N6: =SUMIFS($I$2:$I$201,$F$2:$F$201,M6) -> 96224.24
A7: B006 | B7: P045 | C7: =_xlfn.XLOOKUP(B7,appointments!$B$2:$B$201,appointments!$C$2:$C$201) -> D006 | D7: =_xlfn.XLOOKUP(C7,Doctor!$A$2:$A$11,Doctor!$D$2:$D$11) -> Alex Davis | E7: T006 | F7: =_xlfn.XLOOKUP(E7,Treatment!$A:$A,Treatment!$C:$C) -> Chemotherapy | G7: 45096 | H7: =TEXT(G7,"mmmm-yyyy") -> June-2023 | I7: 1381 | J7: Insurance | K7: Pending | M7: MRI | N7: =SUMIFS($I$2:$I$201,$F$2:$F$201,M7) -> 116098.16
A8: B007 | B8: P001 | C8: =_xlfn.XLOOKUP(B8,appointments!$B$2:$B$201,appointments!$C$2:$C$201) -> D007 | D8: =_xlfn.XLOOKUP(C8,Doctor!$A$2:$A$11,Doctor!$D$2:$D$11) -> Robert Davis | E8: T007 | F8: =_xlfn.XLOOKUP(E8,Treatment!$A:$A,Treatment!$C:$C) -> Chemotherapy | G8: 45025 | H8: =TEXT(G8,"mmmm-yyyy") -> April-2023 | I8: 534.03 | J8: Cash | K8: Failed | M8: Physiotherapy | N8: =SUMIFS($I$2:$I$201,$F$2:$F$201,M8) -> 99418.1
A9: B008 | B9: P016 | C9: =_xlfn.XLOOKUP(B9,appointments!$B$2:$B$201,appointments!$C$2:$C$201) -> D010 | D9: =_xlfn.XLOOKUP(C9,Doctor!$A$2:$A$11,Doctor!$D$2:$D$11) -> Linda Wilson | E9: T008 | F9: =_xlfn.XLOOKUP(E9,Treatment!$A:$A,Treatment!$C:$C) -> Physiotherapy | G9: 45070 | H9: =TEXT(G9,"mmmm-yyyy") -> May-2023 | I9: 3413.64 | J9: Cash | K9: Failed | M9: X-Ray | N9: =SUMIFS($I$2:$I$201,$F$2:$F$201,M9) -> 110653.67
A10: B009 | B10: P039 | C10: =_xlfn.XLOOKUP(B10,appointments!$B$2:$B$201,appointments!$C$2:$C$201) -> D010 | D10: =_xlfn.XLOOKUP(C10,Doctor!$A$2:$A$11,Doctor!$D$2:$D$11) -> Linda Wilson | E10: T009 | F10: =_xlfn.XLOOKUP(E10,Treatment!$A:$A,Treatment!$C:$C) -> Physiotherapy | G10: 44990 | H10: =TEXT(G10,"mmmm-yyyy") -> March-2023 | I10: 4541.14 | J10: Credit Card | K10: Paid
A11: B010 | B11: P005 | C11: =_xlfn.XLOOKUP(B11,appointments!$B$2:$B$201,appointments!$C$2:$C$201) -> D003 | D11: =_xlfn.XLOOKUP(C11,Doctor!$A$2:$A$11,Doctor!$D$2:$D$11) -> Jane Smith | E11: T010 | F11: =_xlfn.XLOOKUP(E11,Treatment!$A:$A,Treatment!$C:$C) -> Physiotherapy | G11: 44939 | H11: =TEXT(G11,"mmmm-yyyy") -> January-2023 | I11: 1595.67 | J11: Cash | K11: Paid
A12: B011 | B12: P022 | C12: =_xlfn.XLOOKUP(B12,appointments!$B$2:$B$201,appointments!$C$2:$C$201) -> D007 | D12: =_xlfn.XLOOKUP(C12,Doctor!$A$2:$A$11,Doctor!$D$2:$D$11) -> Robert Davis | E12: T011 | F12: =_xlfn.XLOOKUP(E12,Treatment!$A:$A,Treatment!$C:$C) -> MRI | G12: 45242 | H12: =TEXT(G12,"mmmm-yyyy") -> November-2023 | I12: 4671.66 | J12: Cash | K12: Failed
A13: B012 | B13: P029 | C13: =_xlfn.XLOOKUP(B13,appointments!$B$2:$B$201,appointments!$C$2:$C$201) -> D003 | D13: =_xlfn.XLOOKUP(C13,Doctor!$A$2:$A$11,Doctor!$D$2:$D$11) -> Jane Smith | E13: T012 | F13: =_xlfn.XLOOKUP(E13,Treatment!$A:$A,Treatment!$C:$C) -> Chemotherapy | G13: 45053 | H13: =TEXT(G13,"mmmm-yyyy") -> May-2023 | I13: 771.2 | J13: Insurance | K13: Pending
A14: B013 | B14: P003 | C14: =_xlfn.XLOOKUP(B14,appointments!$B$2:$B$201,appointments!$C$2:$C$201) -> D002 | D14: =_xlfn.XLOOKUP(C14,Doctor!$A$2:$A$11,Doctor!$D$2:$D$11) -> Jane Davis | E14: T013 | F14: =_xlfn.XLOOKUP(E14,Treatment!$A:$A,Treatment!$C:$C) -> MRI | G14: 45154 | H14: =TEXT(G14,"mmmm-yyyy") -> August-2023 | I14: 4704.96 | J14: Cash | K14: Paid
A15: B014 | B15: P012 | C15: =_xlfn.XLOOKUP(B15,appointments!$B$2:$B$201,appointments!$C$2:$C$201) -> D010 | D15: =_xlfn.XLOOKUP(C15,Doctor!$A$2:$A$11,Doctor!$D$2:$D$11) -> Linda Wilson | E15: T014 | F15: =_xlfn.XLOOKUP(E15,Treatment!$A:$A,Treatment!$C:$C) -> ECG | G15: 45071 | H15: =TEXT(G15,"mmmm-yyyy") -> May-2023 | I15: 2082.3 | J15: Credit Card | K15: Paid
A16: B015 | B16: P026 | C16: =_xlfn.XLOOKUP(B16,appointments!$B$2:$B$201,appointments!$C$2:$C$201) -> D004 | D16: =_xlfn.XLOOKUP(C16,Doctor!$A$2:$A$11,Doctor!$D$2:$D$11) -> David Jones | E16: T015 | F16: =_xlfn.XLOOKUP(E16,Treatment!$A:$A,Treatment!$C:$C) -> Physiotherapy | G16: 44941 | H16: =TEXT(G16,"mmmm-yyyy") -> January-2023 | I16: 956.39 | J16: Insurance | K16: Pending
A17: B016 | B17: P016 | C17: =_xlfn.XLOOKUP(B17,appointments!$B$2:$B$201,appointments!$C$2:$C$201) -> D010 | D17: =_xlfn.XLOOKUP(C17,Doctor!$A$2:$A$11,Doctor!$D$2:$D$11) -> Linda Wilson | E17: T016 | F17: =_xlfn.XLOOKUP(E17,Treatment!$A:$A,Treatment!$C:$C) -> MRI | G17: 45107 | H17: =TEXT(G17,"mmmm-yyyy") -> June-2023 | I17: 2686.42 | J17: Insurance | K17: Paid
A18: B017 | B18: P037 | C18: =_xlfn.XLOOKUP(B18,appointments!$B$2:$B$201,appointments!$C$2:$C$201) -> D009 | D18: =_xlfn.XLOOKUP(C18,Doctor!$A$2:$A$11,Doctor!$D$2:$D$11) -> Sarah Smith | E18: T017 | F18: =_xlfn.XLOOKUP(E18,Treatment!$A:$A,Treatment!$C:$C) -> MRI | G18: 45118 | H18: =TEXT(G18,"mmmm-yyyy") -> July-2023 | I18: 1655.49 | J18: Credit Card | K18: Pending
A19: B018 | B19: P022 | C19: =_xlfn.XLOOKUP(B19,appointments!$B$2:$B$201,appointments!$C$2:$C$201) -> D007 | D19: =_xlfn.XLOOKUP(C19,Doctor!$A$2:$A$11,Doctor!$D$2:$D$11) -> Robert Davis | E19: T018 | F19: =_xlfn.XLOOKUP(E19,Treatment!$A:$A,Treatment!$C:$C) -> ECG | G19: 45244 | H19: =TEXT(G19,"mmmm-yyyy") -> November-2023 | I19: 1781.93 | J19: Insurance | K19: Pending
A20: B019 | B20: P029 | C20: =_xlfn.XLOOKUP(B20,appointments!$B$2:$B$201,appointments!$C$2:$C$201) -> D003 | D20: =_xlfn.XLOOKUP(C20,Doctor!$A$2:$A$11,Doctor!$D$2:$D$11) -> Jane Smith | E20: T019 | F20: =_xlfn.XLOOKUP(E20,Treatment!$A:$A,Treatment!$C:$C) -> X-Ray | G20: 44963 | H20: =TEXT(G20,"mmmm-yyyy") -> February-2023 | I20: 1882.8 | J20: Insurance | K20: Pending
A21: B020 | B21: P014 | C21: =_xlfn.XLOOKUP(B21,appointments!$B$2:$B$201,appointments!$C$2:$C$201) -> D003 | D21: =_xlfn.XLOOKUP(C21,Doctor!$A$2:$A$11,Doctor!$D$2:$D$11) -> Jane Smith | E21: T020 | F21: =_xlfn.XLOOKUP(E21,Treatment!$A:$A,Treatment!$C:$C) -> Chemotherapy | G21: 45265 | H21: =TEXT(G21,"mmmm-yyyy") -> December-2023 | I21: 4113.62 | J21: Credit Card | K21: Failed
... A201: B200 | B201: P007 | C201: =_xlfn.XLOOKUP(B201,appointments!$B$2:$B$201,appointments!$C$2:$C$201) -> D009 | D201: =_xlfn.XLOOKUP(C201,Doctor!$A$2:$A$11,Doctor!$D$2:$D$11) -> Sarah Smith | E201: T200 | F201: =_xlfn.XLOOKUP(E201,Treatment!$A:$A,Treatment!$C:$C) -> X-Ray | G201: 45290 | H201: =TEXT(G201,"mmmm-yyyy") -> December-2023 | I201: 3288.15 | J201: Insurance | K201: Paid

Sheet Sheet3

Sheet Patient
A1: Patient_Id | B1: First_Name | C1: Last_Name | D1: Gender | E1: Date_Of_Birth | F1: Contact_Number | G1: Address | H1: Registration_Date | I1: Insurance_Provider | J1: Insurance_Number | K1: Email
A2: P001 | B2: David | C2: Williams | D2: F | E2: 20244 | F2: 6939585183 | G2: 789 Pine Rd | H2: 44735 | I2: WellnessCorp | J2: INS840674 | K2: david.williams@mail.com
A3: P002 | B3: Emily | C3: Smith | D3: F | E3: 30967 | F3: 8228188767 | G3: 321 Maple Dr | H3: 44576 | I3: PulseSecure | J3: INS354079 | K3: emily.smith@mail.com
A4: P003 | B4: Laura | C4: Jones | D4: M | E4: 28358 | F4: 8397029847 | G4: 321 Maple Dr | H4: 44599 | I4: PulseSecure | J4: INS650929 | K4: laura.jones@mail.com
A5: P004 | B5: Michael | C5: Johnson | D5: F | E5: 29637 | F5: 9019443432 | G5: 123 Elm St | H5: 44257 | I5: HealthIndia | J5: INS789944 | K5: michael.johnson@mail.com
A6: P005 | B6: David | C6: Wilson | D6: M | E6: 22090 | F6: 7734463155 | G6: 123 Elm St | H6: 44468 | I6: MedCare Plus | J6: INS788105 | K6: david.wilson@mail.com
A7: P006 | B7: Linda | C7: Jones | D7: M | E7: 23178 | F7: 7561777264 | G7: 321 Maple Dr | H7: 44836 | I7: HealthIndia | J7: INS613758 | K7: linda.jones@mail.com
A8: P007 | B8: Alex | C8: Johnson | D8: F | E8: 32667 | F8: 6278710077 | G8: 789 Pine Rd | H8: 44555 | I8: MedCare Plus | J8: INS465890 | K8: alex.johnson@mail.com
A9: P008 | B9: David | C9: Davis | D9: F | E9: 27946 | F9: 7090558393 | G9: 456 Oak Ave | H9: 44341 | I9: WellnessCorp | J9: INS545101 | K9: david.davis@mail.com
A10: P009 | B10: Laura | C10: Davis | D10: M | E10: 26278 | F10: 7060324619 | G10: 321 Maple Dr | H10: 44822 | I10: PulseSecure | J10: INS136631 | K10: laura.davis@mail.com
A11: P010 | B11: Michael | C11: Taylor | D11: M | E11: 37177 | F11: 7081396733 | G11: 123 Elm St | H11: 44797 | I11: WellnessCorp | J11: INS866577 | K11: michael.taylor@mail.com
A12: P011 | B12: Emily | C12: Jones | D12: F | E12: 24445 | F12: 8990604070 | G12: 789 Pine Rd | H12: 44831 | I12: MedCare Plus | J12: INS172991 | K12: emily.jones@mail.com
A13: P012 | B13: Laura | C13: Davis | D13: F | E13: 33580 | F13: 8135666049 | G13: 321 Maple Dr | H13: 45043 | I13: MedCare Plus | J13: INS104014 | K13: laura.davis@mail.com
... A51: P050 | B51: Laura | C51: Wilson | D51: M | E51: 34330 | F51: 8301134730 | G51: 321 Maple Dr | H51: 45044 | I51: WellnessCorp | J51: INS712210 | K51: laura.wilson@mail.com

Sheet Sheet5

Sheet Treatment
A1: Treatment_Id | B1: Appointment_Id | C1: Treatment_Type | D1: Description | E1: Cost | F1: Treatment_Date
A2: T001 | B2: A001 | C2: Chemotherapy | D2: Basic screening | E2: 3941.97 | F2: 45147
A3: T002 | B3: A002 | C3: MRI | D3: Advanced protocol | E3: 4158.44 | F3: 45086
A4: T003 | B4: A003 | C4: MRI | D4: Standard procedure | E4: 3731.55 | F4: 45105
A5: T004 | B5: A004 | C5: MRI | D5: Basic screening | E5: 4799.86 | F5: 45170
A6: T005 | B6: A005 | C6: ECG | D6: Standard procedure | E6: 582.05 | F6: 45113 | H6: =AVERAGE(E2:E201) -> 2756.2493
A7: T006 | B7: A006 | C7: Chemotherapy | D7: Standard procedure | E7: 1381 | F7: 45096
A8: T007 | B8: A007 | C8: Chemotherapy | D8: Advanced protocol | E8: 534.03 | F8: 45025
A9: T008 | B9: A008 | C9: Physiotherapy | D9: Basic screening | E9: 3413.64 | F9: 45070
A10: T009 | B10: A009 | C10: Physiotherapy | D10: Standard procedure | E10: 4541.14 | F10: 44990 | H10: =AVERAGE(E2:E201) -> 2756.2493
A11: T010 | B11: A010 | C11: Physiotherapy | D11: Standard procedure | E11: 1595.67 | F11: 44939
A12: T011 | B12: A011 | C12: MRI | D12: Basic screening | E12: 4671.66 | F12: 45242
A13: T012 | B13: A012 | C13: Chemotherapy | D13: Standard procedure | E13: 771.2 | F13: 45053 | I13: 2756.2493
A14: T013 | B14: A013 | C14: MRI | D14: Standard procedure | E14: 4704.96 | F14: 45154
A15: T014 | B15: A014 | C15: ECG | D15: Basic screening | E15: 2082.3 | F15: 45071
A16: T015 | B16: A015 | C16: Physiotherapy | D16: Basic screening | E16: 956.39 | F16: 44941
A17: T016 | B17: A016 | C17: MRI | D17: Basic screening | E17: 2686.42 | F17: 45107
A18: T017 | B18: A017 | C18: MRI | D18: Basic screening | E18: 1655.49 | F18: 45118 | J18: =H10 -> 2756.2493
A19: T018 | B19: A018 | C19: ECG | D19: Advanced protocol | E19: 1781.93 | F19: 45244
A20: T019 | B20: A019 | C20: X-Ray | D20: Basic screening | E20: 1882.8 | F20: 44963
A21: T020 | B21: A020 | C21: Chemotherapy | D21: Advanced protocol | E21: 4113.62 | F21: 45265
A22: T021 | B22: A021 | C22: X-Ray | D22: Advanced protocol | E22: 2926.23 | F22: 45040
A23: T022 | B23: A022 | C23: Physiotherapy | D23: Advanced protocol | E23: 1900.88 | F23: 45244
A24: T023 | B24: A023 | C24: MRI | D24: Standard procedure | E24: 3246.5 | F24: 45055
A25: T024 | B25: A024 | C25: ECG | D25: Advanced protocol | E25: 3722.68 | F25: 45098
A26: T025 | B26: A025 | C26: ECG | D26: Advanced protocol | E26: 1726.81 | F26: 44982
A27: T026 | B27: A026 | C27: Chemotherapy | D27: Standard procedure | E27: 2360.97 | F27: 45002
A28: T027 | B28: A027 | C28: X-Ray | D28: Standard procedure | E28: 1048.49 | F28: 45244
A29: T028 | B29: A028 | C29: Chemotherapy | D29: Standard procedure | E29: 1315.17 | F29: 45228
A30: T029 | B30: A029 | C30: MRI | D30: Basic screening | E30: 3565.03 | F30: 45102
... A201: T200 | B201: A200 | C201: X-Ray | D201: Basic screening | E201: 3288.15 | F201: 45290

Sheet Sheet6

Sheet Doctor
A1: Doctor_Id | B1: First_Name | C1: Last_Name | D1: Full Name | E1: Specialization | F1: Phone_Number | G1: Years_Experience | H1: Hospital_Branch | I1: Email
A2: D001 | B2: David | C2: Taylor | D2: =_xlfn.CONCAT(B2," ",C2) -> David Taylor | E2: Dermatology | F2: 8322010158 | G2: 17 | H2: Westside Clinic | I2: dr.david.taylor@hospital.com
A3: D002 | B3: Jane | C3: Davis | D3: =_xlfn.CONCAT(B3," ",C3) -> Jane Davis | E3: Pediatrics | F3: 9004382050 | G3: 24 | H3: Eastside Clinic | I3: dr.jane.davis@hospital.com
A4: D003 | B4: Jane | C4: Smith | D4: =_xlfn.CONCAT(B4," ",C4) -> Jane Smith | E4: Pediatrics | F4: 8737740598 | G4: 19 | H4: Eastside Clinic | I4: dr.jane.smith@hospital.com
A5: D004 | B5: David | C5: Jones | D5: =_xlfn.CONCAT(B5," ",C5) -> David Jones | E5: Pediatrics | F5: 6594221991 | G5: 28 | H5: Central Hospital | I5: dr.david.jones@hospital.com
A6: D005 | B6: Sarah | C6: Taylor | D6: =_xlfn.CONCAT(B6," ",C6) -> Sarah Taylor | E6: Dermatology | F6: 9118538547 | G6: 26 | H6: Central Hospital | I6: dr.sarah.taylor@hospital.com
A7: D006 | B7: Alex | C7: Davis | D7: =_xlfn.CONCAT(B7," ",C7) -> Alex Davis | E7: Pediatrics | F7: 6570137231 | G7: 23 | H7: Central Hospital | I7: dr.alex.davis@hospital.com
A8: D007 | B8: Robert | C8: Davis | D8: =_xlfn.CONCAT(B8," ",C8) -> Robert Davis | E8: Oncology | F8: 8217493115 | G8: 26 | H8: Westside Clinic | I8: dr.robert.davis@hospital.com
A9: D008 | B9: Linda | C9: Brown | D9: =_xlfn.CONCAT(B9," ",C9) -> Linda Brown | E9: Dermatology | F9: 9069162601 | G9: 5 | H9: Westside Clinic | I9: dr.linda.brown@hospital.com
A10: D009 | B10: Sarah | C10: Smith | D10: =_xlfn.CONCAT(B10," ",C10) -> Sarah Smith | E10: Pediatrics | F10: 7387087517 | G10: 26 | H10: Central Hospital | I10: dr.sarah.smith@hospital.com
A11: D010 | B11: Linda | C11: Wilson | D11: =_xlfn.CONCAT(B11," ",C11) -> Linda Wilson | E11: Oncology | F11: 6176383634 | G11: 21 | H11: Eastside Clinic | I11: dr.linda.wilson@hospital.com

Sheet ANALYISIS
A4: 1. Which doctors have the highest number of appointments? | B4: Sarah Taylor
A5: 2. What are the most common reasons for patient visits? | B5: most commonly the patients are coming for checkup and consultation
A6: 3. Which treatment types generate the highest billing revenue? | B6: Chemotherapy | C6: 128855.68
A7: 4. What is the monthly trend of hospital billing revenue?
A8: 5. Which doctors generate the highest billing revenue? | B8: Jane Smith | C8: 95000.59
A10: 4. What is the monthly trend of hospital billing revenue?
C21: Chemotherapy | D21: 128855.68
C22: ECG | D22: 96224.24
C23: MRI | D23: 116098.16
C24: Physiotherapy | D24: 99418.1
C25: X-Ray | D25: 110653.67

Sheet CHANGE LOG
C3: CHANGE LOG
C8: STEP | D8: SHEET | E8: CHANGE MADE
C9: 1 | D9: All datasets | E9: Checked Duplicate appoinment IDs,bill IDs & treatment IDs & No Duplicates found
C10: 2 | D10: All datasets | E10: Checked Missing Values and No Missing values Founded
C11: 3 | D11: All datasets | E11: Added all data to data modelling
C12: 4 | D12: Billing | E12: Added docter ID & Name and Treatment Type Using XLOOKUP
C13: 5 | D13: Appoinment | E13: Added doctor name using xlookup
C14: 6 | D14: Doctor | E14: Added a column full name with concat fuction

Sheet PIVIOT
B3: Row Labels | C3: Count of Appointment_Id
B4: Alex Davis | C4: 24
B5: David Jones | C5: 14
B6: David Taylor | C6: 25
B7: Jane Davis | C7: 21
B8: Jane Smith | C8: 22
B9: Linda Brown | C9: 16
B10: Linda Wilson | C10: 19
B11: Robert Davis | C11: 13
B12: Sarah Smith | C12: 17
B13: Sarah Taylor | C13: 29
B14: Grand Total | C14: 200
O15: =GETPIVOTDATA("[Measures].[Count of Appointment_Id]",$B$3) -> 200
B26: Row Labels | C26: Count of Patient_Id
B27: Therapy | C27: 42
B28: Checkup | C28: 45
B29: Consultation | C29: 43
B30: Follow-up | C30: 41
B31: Emergency | C31: 29
B32: Grand Total | C32: 200
B40: Row Labels | C40: Sum of Amount
B41: Chemotherapy | C41: 128855.68
B42: ECG | C42: 96224.24
B43: MRI | C43: 116098.16 | P43: =AVERAGE(GETPIVOTDATA("[Measures].[Sum of Amount]",$B$40)) -> 551249.85
B44: Physiotherapy | C44: 99418.1
B45: X-Ray | C45: 110653.67
B46: Grand Total | C46: 551249.85 | P46: =GETPIVOTDATA("[Measures].[Sum of Amount]",$B$40) -> 551249.85
B59: Row Labels | C59: Sum of Amount
B60: April-2023 | C60: 64271.54
B61: August-2023 | C61: 41958.67
B62: December-2023 | C62: 27569.71
B63: February-2023 | C63: 36669.69
B64: January-2023 | C64: 58701.23
B65: July-2023 | C65: 39880.19
B66: June-2023 | C66: 56887.82
B67: March-2023 | C67: 47304.29
B68: May-2023 | C68: 48791.05
B69: November-2023 | C69: 52474.98
B70: October-2023 | C70: 43314.15
B71: September-2023 | C71: 33426.53
...

Sheet CHARTS
A1: Hospital Management CHARTS

Sheet DASHBOARD

Sheet Sheet4
E2: RECOMMENDATIONS
E4: Identify doctors with the highest appointment volumes and optimize their schedules.
E5: Promote and improve high-revenue treatments such as Chemotherapy while maintaining quality of care.
E6: Track monthly billing trends and investigate months with unusually low revenue.
E7: Study high-revenue doctors and understand which treatments/services drive their revenue.
